Workbook

Sheet MOV_ESTUD_HACIA_COLOMBIA
A1: AÑO | B1: SEMESTRE | C1: ID_TIPO_DOCUMENTO | D1: NUM_DOCUMENTO | E1: PRIMER_NOMBRE | F1: SEGUNDO_NOMBRE | G1: PRIMER_APELLIDO | H1: SEGUNDO_APELLIDO | I1: PAIS_EXTRANJERO | J1: ID_PAIS_EXTRANJERO | K1: INSTITUCION_EXTRANJERA | L1: TIPO_MOV_EST_EXTRANJ | M1: ID_TIPO_MOV_EST_EXTRANJ | N1: NUM_DIAS_MOVILIDAD | O1: MOVILIDAD_POR_CONVENIO | P1: CODIGO_CONVENIO | Q1: FUENTE_NACIONAL_INVESTIG | R1: ID_FUENTE_NACIONAL_INVESTIG | S1: VALOR_FINANCIACION_NACIONAL | T1: FUENTE_INTERNACIONAL | U1: ID_FUENTE_INTERNACIONAL | V1: PAIS_FINANCIADOR | W1: ID_PAIS_FINANCIADOR | X1: VALOR_FINANCIACION_INTERNAC
A2: 2025 | B2: 1 | C2: PS | D2: G32986297 | E2: Jesús | F2: Eduardo | G2: Martínez | H2: López | I2: MÉXICO | J2: =VLOOKUP(I2,BD!B$1:C$261,2,FALSE) -> 484 | K2: Econométrica | L2: Curso corto | M2: =VLOOKUP(L2,BD!D$1:E$6,2,FALSE) -> 3 | N2: 7 | O2: N | R2: =VLOOKUP(Q2,BD!F$1:G$22,2,FALSE) -> #N/A | T2: Organismo Multilateral | U2: =VLOOKUP(T2,BD!H$1:I$8,2,FALSE) -> 7 | V2: MÉXICO | W2: =VLOOKUP(V2,BD!B$1:C$261,2,FALSE) -> 484 | X2: 5315000
A3: 2025 | B3: 1 | C3: PS | D3: U32610501 | E3: Arzu | G3: Kirayoglu | I3: TURQUÍA | J3: =VLOOKUP(I3,BD!B$1:C$261,2,FALSE) -> 792 | K3: Innética | L3: Curso corto | M3: =VLOOKUP(L3,BD!D$1:E$6,2,FALSE) -> 3 | N3: 7 | O3: N | R3: =VLOOKUP(Q3,BD!F$1:G$22,2,FALSE) -> #N/A | T3: Organismo Multilateral | U3: =VLOOKUP(T3,BD!H$1:I$8,2,FALSE) -> 7 | V3: ESPAÑA | W3: =VLOOKUP(V3,BD!B$1:C$261,2,FALSE) -> 724 | X3: 5315000
A4: 2025 | B4: 1 | C4: PS | D4: N04903220 | E4: Daphne | F4: Melissa | G4: Cabrera | H4: Tapia | I4: MÉXICO | J4: =VLOOKUP(I4,BD!B$1:C$261,2,FALSE) -> 484 | K4: Econométrica | L4: Curso corto | M4: =VLOOKUP(L4,BD!D$1:E$6,2,FALSE) -> 3 | N4: 7 | O4: N | R4: =VLOOKUP(Q4,BD!F$1:G$22,2,FALSE) -> #N/A | T4: Organismo Multilateral | U4: =VLOOKUP(T4,BD!H$1:I$8,2,FALSE) -> 7 | V4: MÉXICO | W4: =VLOOKUP(V4,BD!B$1:C$261,2,FALSE) -> 484 | X4: 5315000
A5: 2025 | B5: 1 | C5: PS | D5: 64640289 | E5: Catalin | G5: Serbu | I5: RUMANÍA | J5: =VLOOKUP(I5,BD!B$1:C$261,2,FALSE) -> 642 | K5: Innética | L5: Curso corto | M5: =VLOOKUP(L5,BD!D$1:E$6,2,FALSE) -> 3 | N5: 7 | O5: N | R5: =VLOOKUP(Q5,BD!F$1:G$22,2,FALSE) -> #N/A | T5: Organismo Multilateral | U5: =VLOOKUP(T5,BD!H$1:I$8,2,FALSE) -> 7 | V5: ESPAÑA | W5: =VLOOKUP(V5,BD!B$1:C$261,2,FALSE) -> 724 | X5: 5315000
A6: 2025 | B6: 1 | C6: PS | D6: PAP274959 | E6: Luis | F6: José | G6: Callarisa | H6: Fiol | I6: ESPAÑA | J6: =VLOOKUP(I6,BD!B$1:C$261,2,FALSE) -> 724 | K6: Innética | L6: Curso corto | M6: =VLOOKUP(L6,BD!D$1:E$6,2,FALSE) -> 3 | N6: 7 | O6: N | R6: =VLOOKUP(Q6,BD!F$1:G$22,2,FALSE) -> #N/A | T6: Organismo Multilateral | U6: =VLOOKUP(T6,BD!H$1:I$8,2,FALSE) -> 7 | V6: ESPAÑA | W6: =VLOOKUP(V6,BD!B$1:C$261,2,FALSE) -> 724 | X6: 5315000
A7: 2025 | B7: 1 | C7: PS | D7: AT8181419 | E7: Ioanna | G7: Papadaki | I7: GRECIA | J7: =VLOOKUP(I7,BD!B$1:C$261,2,FALSE) -> 300 | K7: Action | L7: Curso corto | M7: =VLOOKUP(L7,BD!D$1:E$6,2,FALSE) -> 3 | N7: 7 | O7: N | R7: =VLOOKUP(Q7,BD!F$1:G$22,2,FALSE) -> #N/A | T7: Organismo Multilateral | U7: =VLOOKUP(T7,BD!H$1:I$8,2,FALSE) -> 7 | V7: GRECIA | W7: =VLOOKUP(V7,BD!B$1:C$261,2,FALSE) -> 300 | X7: 5315000
A8: 2025 | B8: 1 | C8: PS | D8: A81664118 | E8: Stephanie | F8: Aline | G8: Morales | I8: ESTADOS UNIDOS DE AMÉRICA | J8: =VLOOKUP(I8,BD!B$1:C$261,2,FALSE) -> 840 | K8: Econométrica | L8: Curso corto | M8: =VLOOKUP(L8,BD!D$1:E$6,2,FALSE) -> 3 | N8: 7 | O8: N | R8: =VLOOKUP(Q8,BD!F$1:G$22,2,FALSE) -> #N/A | T8: Organismo Multilateral | U8: =VLOOKUP(T8,BD!H$1:I$8,2,FALSE) -> 7 | V8: MÉXICO | W8: =VLOOKUP(V8,BD!B$1:C$261,2,FALSE) -> 484 | X8: 5315000
A9: 2025 | B9: 1 | C9: PS | D9: PAO684528 | E9: Cristina | G9: Díaz | H9: Dobarro | I9: ESPAÑA | J9: =VLOOKUP(I9,BD!B$1:C$261,2,FALSE) -> 724 | K9: Innética | L9: Curso corto | M9: =VLOOKUP(L9,BD!D$1:E$6,2,FALSE) -> 3 | N9: 7 | O9: N | R9: =VLOOKUP(Q9,BD!F$1:G$22,2,FALSE) -> #N/A | T9: Organismo Multilateral | U9: =VLOOKUP(T9,BD!H$1:I$8,2,FALSE) -> 7 | V9: ESPAÑA | W9: =VLOOKUP(V9,BD!B$1:C$261,2,FALSE) -> 724 | X9: 5315000
A10: 2025 | B10: 1 | C10: PS | D10: N16400418 | E10: Alberto | F10: Carlos | G10: Becerra | H10: Lopez | I10: MÉXICO | J10: =VLOOKUP(I10,BD!B$1:C$261,2,FALSE) -> 484 | K10: Econométrica | L10: Curso corto | M10: =VLOOKUP(L10,BD!D$1:E$6,2,FALSE) -> 3 | N10: 7 | O10: N | R10: =VLOOKUP(Q10,BD!F$1:G$22,2,FALSE) -> #N/A | T10: Organismo Multilateral | U10: =VLOOKUP(T10,BD!H$1:I$8,2,FALSE) -> 7 | V10: MÉXICO | W10: =VLOOKUP(V10,BD!B$1:C$261,2,FALSE) -> 484 | X10: 5315000
A11: 2025 | B11: 1 | C11: PS | D11: AY1243075 | E11: Vasiliki | G11: Nakou | I11: GRECIA | J11: =VLOOKUP(I11,BD!B$1:C$261,2,FALSE) -> 300 | K11: Action | L11: Curso corto | M11: =VLOOKUP(L11,BD!D$1:E$6,2,FALSE) -> 3 | N11: 7 | O11: N | R11: =VLOOKUP(Q11,BD!F$1:G$22,2,FALSE) -> #N/A | T11: Organismo Multilateral | U11: =VLOOKUP(T11,BD!H$1:I$8,2,FALSE) -> 7 | V11: GRECIA | W11: =VLOOKUP(V11,BD!B$1:C$261,2,FALSE) -> 300 | X11: 5315000
A12: 2025 | B12: 1 | C12: PS | D12: BA5681779 | E12: Panagiota | G12: Pata | I12: GRECIA | J12: =VLOOKUP(I12,BD!B$1:C$261,2,FALSE) -> 300 | K12: Action | L12: Curso corto | M12: =VLOOKUP(L12,BD!D$1:E$6,2,FALSE) -> 3 | N12: 7 | O12: N | R12: =VLOOKUP(Q12,BD!F$1:G$22,2,FALSE) -> #N/A | T12: Organismo Multilateral | U12: =VLOOKUP(T12,BD!H$1:I$8,2,FALSE) -> 7 | V12: GRECIA | W12: =VLOOKUP(V12,BD!B$1:C$261,2,FALSE) -> 300 | X12: 5315000
A13: 2025 | B13: 1 | C13: PS | D13: BA7177723 | E13: Antonios | G13: Fitsakis | I13: GRECIA | J13: =VLOOKUP(I13,BD!B$1:C$261,2,FALSE) -> 300 | K13: Action | L13: Curso corto | M13: =VLOOKUP(L13,BD!D$1:E$6,2,FALSE) -> 3 | N13: 7 | O13: N | R13: =VLOOKUP(Q13,BD!F$1:G$22,2,FALSE) -> #N/A | T13: Organismo Multilateral | U13: =VLOOKUP(T13,BD!H$1:I$8,2,FALSE) -> 7 | V13: GRECIA | W13: =VLOOKUP(V13,BD!B$1:C$261,2,FALSE) -> 300 | X13: 5315000
A14: 2025 | B14: 1 | C14: PS | D14: BA6953056 | E14: Anastasia | G14: Tzortzakaki | I14: GRECIA | J14: =VLOOKUP(I14,BD!B$1:C$261,2,FALSE) -> 300 | K14: Action | L14: Curso corto | M14: =VLOOKUP(L14,BD!D$1:E$6,2,FALSE) -> 3 | N14: 7 | O14: N | R14: =VLOOKUP(Q14,BD!F$1:G$22,2,FALSE) -> #N/A | T14: Organismo Multilateral | U14: =VLOOKUP(T14,BD!H$1:I$8,2,FALSE) -> 7 | V14: GRECIA | W14: =VLOOKUP(V14,BD!B$1:C$261,2,FALSE) -> 300 | X14: 5315000
A15: 2025 | B15: 1 | C15: PS | D15: G33869713 | E15: Andrea | G15: Ramirez | H15: Rico | I15: MÉXICO | J15: =VLOOKUP(I15,BD!B$1:C$261,2,FALSE) -> 484 | K15: Econométrica | L15: Curso corto | M15: =VLOOKUP(L15,BD!D$1:E$6,2,FALSE) -> 3 | N15: 7 | O15: N | R15: =VLOOKUP(Q15,BD!F$1:G$22,2,FALSE) -> #N/A | T15: Organismo Multilateral | U15: =VLOOKUP(T15,BD!H$1:I$8,2,FALSE) -> 7 | V15: MÉXICO | W15: =VLOOKUP(V15,BD!B$1:C$261,2,FALSE) -> 484 | X15: 5315000
A16: 2025 | B16: 1 | C16: PS | D16: N17573865 | E16: Ivan | G16: Dominguez | H16: Reyes | I16: MÉXICO | J16: =VLOOKUP(I16,BD!B$1:C$261,2,FALSE) -> 484 | K16: Econométrica | L16: Curso corto | M16: =VLOOKUP(L16,BD!D$1:E$6,2,FALSE) -> 3 | N16: 7 | O16: N | R16: =VLOOKUP(Q16,BD!F$1:G$22,2,FALSE) -> #N/A | T16: Organismo Multilateral | U16: =VLOOKUP(T16,BD!H$1:I$8,2,FALSE) -> 7 | V16: MÉXICO | W16: =VLOOKUP(V16,BD!B$1:C$261,2,FALSE) -> 484 | X16: 5315000
A17: 2025 | B17: 1 | C17: PS | D17: N17345673 | E17: Diana | F17: Lisset | G17: Mondragón | H17: Rivera | I17: MÉXICO | J17: =VLOOKUP(I17,BD!B$1:C$261,2,FALSE) -> 484 | K17: Econométrica | L17: Curso corto | M17: =VLOOKUP(L17,BD!D$1:E$6,2,FALSE) -> 3 | N17: 7 | O17: N | R17: =VLOOKUP(Q17,BD!F$1:G$22,2,FALSE) -> #N/A | T17: Organismo Multilateral | U17: =VLOOKUP(T17,BD!H$1:I$8,2,FALSE) -> 7 | V17: MÉXICO | W17: =VLOOKUP(V17,BD!B$1:C$261,2,FALSE) -> 484 | X17: 5315000
A18: 2025 | B18: 1 | C18: PS | D18: YC2005680 | E18: Eleonora | G18: Masullo | I18: ITALIA | J18: =VLOOKUP(I18,BD!B$1:C$261,2,FALSE) -> 380 | K18: RAS | L18: Curso corto | M18: =VLOOKUP(L18,BD!D$1:E$6,2,FALSE) -> 3 | N18: 7 | O18: N | R18: =VLOOKUP(Q18,BD!F$1:G$22,2,FALSE) -> #N/A | T18: Organismo Multilateral | U18: =VLOOKUP(T18,BD!H$1:I$8,2,FALSE) -> 7 | V18: ITALIA | W18: =VLOOKUP(V18,BD!B$1:C$261,2,FALSE) -> 380 | X18: 5315000
A19: 2025 | B19: 1 | C19: PS | D19: YB9580835 | E19: Barbara | G19: Amoruso | I19: ITALIA | J19: =VLOOKUP(I19,BD!B$1:C$261,2,FALSE) -> 380 | K19: RAS | L19: Curso corto | M19: =VLOOKUP(L19,BD!D$1:E$6,2,FALSE) -> 3 | N19: 7 | O19: N | R19: =VLOOKUP(Q19,BD!F$1:G$22,2,FALSE) -> #N/A | T19: Organismo Multilateral | U19: =VLOOKUP(T19,BD!H$1:I$8,2,FALSE) -> 7 | V19: ITALIA | W19: =VLOOKUP(V19,BD!B$1:C$261,2,FALSE) -> 380 | X19: 5315000
A20: 2025 | B20: 1 | C20: PS | D20: 193647147 | E20: Richard | F20: Humberto | G20: Mogollón | H20: Ortega | I20: VENEZUELA | J20: =VLOOKUP(I20,BD!B$1:C$261,2,FALSE) -> 862 | K20: Cooperbom | L20: Curso corto | M20: =VLOOKUP(L20,BD!D$1:E$6,2,FALSE) -> 3 | N20: 7 | O20: N | R20: =VLOOKUP(Q20,BD!F$1:G$22,2,FALSE) -> #N/A | T20: Organismo Multilateral | U20: =VLOOKUP(T20,BD!H$1:I$8,2,FALSE) -> 7 | V20: BRASIL | W20: =VLOOKUP(V20,BD!B$1:C$261,2,FALSE) -> 76 | X20: 5315000
A21: 2025 | B21: 1 | C21: PS | D21: FP662215 | E21: Lueny | G21: De Souza | H21: Rodriguez | I21: BRASIL | J21: =VLOOKUP(I21,BD!B$1:C$261,2,FALSE) -> 76 | K21: Cooperbom | L21: Curso corto | M21: =VLOOKUP(L21,BD!D$1:E$6,2,FALSE) -> 3 | N21: 7 | O21: N | R21: =VLOOKUP(Q21,BD!F$1:G$22,2,FALSE) -> #N/A | T21: Organismo Multilateral | U21: =VLOOKUP(T21,BD!H$1:I$8,2,FALSE) -> 7 | V21: BRASIL | W21: =VLOOKUP(V21,BD!B$1:C$261,2,FALSE) -> 76 | X21: 5315000
A22: 2025 | B22: 1 | C22: PS | D22: FW998321 | E22: Luciana | G22: Souza | H22: Pena | I22: BRASIL | J22: =VLOOKUP(I22,BD!B$1:C$261,2,FALSE) -> 76 | K22: Cooperbom | L22: Curso corto | M22: =VLOOKUP(L22,BD!D$1:E$6,2,FALSE) -> 3 | N22: 7 | O22: N | R22: =VLOOKUP(Q22,BD!F$1:G$22,2,FALSE) -> #N/A | T22: Organismo Multilateral | U22: =VLOOKUP(T22,BD!H$1:I$8,2,FALSE) -> 7 | V22: BRASIL | W22: =VLOOKUP(V22,BD!B$1:C$261,2,FALSE) -> 76 | X22: 5315000
A23: 2025 | B23: 1 | C23: PS | D23: YC0350161 | E23: Marcello | G23: Gravante | I23: ITALIA | J23: =VLOOKUP(I23,BD!B$1:C$261,2,FALSE) -> 380 | K23: RAS | L23: Curso corto | M23: =VLOOKUP(L23,BD!D$1:E$6,2,FALSE) -> 3 | N23: 7 | O23: N | R23: =VLOOKUP(Q23,BD!F$1:G$22,2,FALSE) -> #N/A | T23: Organismo Multilateral | U23: =VLOOKUP(T23,BD!H$1:I$8,2,FALSE) -> 7 | V23: ITALIA | W23: =VLOOKUP(V23,BD!B$1:C$261,2,FALSE) -> 380 | X23: 5315000
A24: 2025 | B24: 1 | C24: PS | D24: YC8269362 | E24: Marialaura | G24: Amato | I24: ITALIA | J24: =VLOOKUP(I24,BD!B$1:C$261,2,FALSE) -> 380 | K24: RAS | L24: Curso corto | M24: =VLOOKUP(L24,BD!D$1:E$6,2,FALSE) -> 3 | N24: 7 | O24: N | R24: =VLOOKUP(Q24,BD!F$1:G$22,2,FALSE) -> #N/A | T24: Organismo Multilateral | U24: =VLOOKUP(T24,BD!H$1:I$8,2,FALSE) -> 7 | V24: ITALIA | W24: =VLOOKUP(V24,BD!B$1:C$261,2,FALSE) -> 380 | X24: 5315000
A25: 2025 | B25: 1 | C25: PS | D25: YB9771090 | E25: Delia | G25: Accardo | I25: ITALIA | J25: =VLOOKUP(I25,BD!B$1:C$261,2,FALSE) -> 380 | K25: RAS | L25: Curso corto | M25: =VLOOKUP(L25,BD!D$1:E$6,2,FALSE) -> 3 | N25: 7 | O25: N | R25: =VLOOKUP(Q25,BD!F$1:G$22,2,FALSE) -> #N/A | T25: Organismo Multilateral | U25: =VLOOKUP(T25,BD!H$1:I$8,2,FALSE) -> 7 | V25: ITALIA | W25: =VLOOKUP(V25,BD!B$1:C$261,2,FALSE) -> 380 | X25: 5315000
A26: 2025 | B26: 1 | C26: PS | D26: GK650420 | E26: Jean | G26: Santos Oliveira | H26: Pereira | I26: BRASIL | J26: =VLOOKUP(I26,BD!B$1:C$261,2,FALSE) -> 76 | K26: Cooperbom | L26: Curso corto | M26: =VLOOKUP(L26,BD!D$1:E$6,2,FALSE) -> 3 | N26: 7 | O26: N | R26: =VLOOKUP(Q26,BD!F$1:G$22,2,FALSE) -> #N/A | T26: Organismo Multilateral | U26: =VLOOKUP(T26,BD!H$1:I$8,2,FALSE) -> 7 | V26: BRASIL | W26: =VLOOKUP(V26,BD!B$1:C$261,2,FALSE) -> 76 | X26: 5315000
A27: 2025 | B27: 1 | C27: PS | D27: FR117719 | E27: Larissa | G27: Costa | I27: BRASIL | J27: =VLOOKUP(I27,BD!B$1:C$261,2,FALSE) -> 76 | K27: Cooperbom | L27: Curso corto | M27: =VLOOKUP(L27,BD!D$1:E$6,2,FALSE) -> 3 | N27: 7 | O27: N | R27: =VLOOKUP(Q27,BD!F$1:G$22,2,FALSE) -> #N/A | T27: Organismo Multilateral | U27: =VLOOKUP(T27,BD!H$1:I$8,2,FALSE) -> 7 | V27: BRASIL | W27: =VLOOKUP(V27,BD!B$1:C$261,2,FALSE) -> 76 | X27: 5315000
A28: 2025 | B28: 1 | C28: PS | D28: N14891363 | E28: Noe | G28: Mejía | H28: Carrascal | I28: MÉXICO | J28: =VLOOKUP(I28,BD!B$1:C$261,2,FALSE) -> 484 | K28: Econométrica | L28: Curso corto | M28: =VLOOKUP(L28,BD!D$1:E$6,2,FALSE) -> 3 | N28: 7 | O28: N | R28: =VLOOKUP(Q28,BD!F$1:G$22,2,FALSE) -> #N/A | T28: Organismo Multilateral | U28: =VLOOKUP(T28,BD!H$1:I$8,2,FALSE) -> 7 | V28: MÉXICO | W28: =VLOOKUP(V28,BD!B$1:C$261,2,FALSE) -> 484 | X28: 5315000
J29: =VLOOKUP(I29,BD!B$1:C$261,2,FALSE) -> #N/A | M29: =VLOOKUP(L29,BD!D$1:E$6,2,FALSE) -> #N/A | R29: =VLOOKUP(Q29,BD!F$1:G$22,2,FALSE) -> #N/A | U29: =VLOOKUP(T29,BD!H$1:I$8,2,FALSE) -> #N/A | W29: =VLOOKUP(V29,BD!B$1:C$261,2,FALSE) -> #N/A
J30: =VLOOKUP(I30,BD!B$1:C$261,2,FALSE) -> #N/A | M30: =VLOOKUP(L30,BD!D$1:E$6,2,FALSE) -> #N/A | R30: =VLOOKUP(Q30,BD!F$1:G$22,2,FALSE) -> #N/A | U30: =VLOOKUP(T30,BD!H$1:I$8,2,FALSE) -> #N/A | W30: =VLOOKUP(V30,BD!B$1:C$261,2,FALSE) -> #N/A
J31: =VLOOKUP(I31,BD!B$1:C$261,2,FALSE) -> #N/A | M31: =VLOOKUP(L31,BD!D$1:E$6,2,FALSE) -> #N/A | R31: =VLOOKUP(Q31,BD!F$1:G$22,2,FALSE) -> #N/A | U31: =VLOOKUP(T31,BD!H$1:I$8,2,FALSE) -> #N/A | W31: =VLOOKUP(V31,BD!B$1:C$261,2,FALSE) -> #N/A
J32: =VLOOKUP(I32,BD!B$1:C$261,2,FALSE) -> #N/A | M32: =VLOOKUP(L32,BD!D$1:E$6,2,FALSE) -> #N/A | R32: =VLOOKUP(Q32,BD!F$1:G$22,2,FALSE) -> #N/A | U32: =VLOOKUP(T32,BD!H$1:I$8,2,FALSE) -> #N/A | W32: =VLOOKUP(V32,BD!B$1:C$261,2,FALSE) -> #N/A
J33: =VLOOKUP(I33,BD!B$1:C$261,2,FALSE) -> #N/A | M33: =VLOOKUP(L33,BD!D$1:E$6,2,FALSE) -> #N/A | R33: =VLOOKUP(Q33,BD!F$1:G$22,2,FALSE) -> #N/A | U33: =VLOOKUP(T33,BD!H$1:I$8,2,FALSE) -> #N/A | W33: =VLOOKUP(V33,BD!B$1:C$261,2,FALSE) -> #N/A
J34: =VLOOKUP(I34,BD!B$1:C$261,2,FALSE) -> #N/A | M34: =VLOOKUP(L34,BD!D$1:E$6,2,FALSE) -> #N/A | R34: =VLOOKUP(Q34,BD!F$1:G$22,2,FALSE) -> #N/A | U34: =VLOOKUP(T34,BD!H$1:I$8,2,FALSE) -> #N/A | W34: =VLOOKUP(V34,BD!B$1:C$261,2,FALSE) -> #N/A
J35: =VLOOKUP(I35,BD!B$1:C$261,2,FALSE) -> #N/A | M35: =VLOOKUP(L35,BD!D$1:E$6,2,FALSE) -> #N/A | R35: =VLOOKUP(Q35,BD!F$1:G$22,2,FALSE) -> #N/A | U35: =VLOOKUP(T35,BD!H$1:I$8,2,FALSE) -> #N/A | W35: =VLOOKUP(V35,BD!B$1:C$261,2,FALSE) -> #N/A
J36: =VLOOKUP(I36,BD!B$1:C$261,2,FALSE) -> #N/A | M36: =VLOOKUP(L36,BD!D$1:E$6,2,FALSE) -> #N/A | R36: =VLOOKUP(Q36,BD!F$1:G$22,2,FALSE) -> #N/A | U36: =VLOOKUP(T36,BD!H$1:I$8,2,FALSE) -> #N/A | W36: =VLOOKUP(V36,BD!B$1:C$261,2,FALSE) -> #N/A
J37: =VLOOKUP(I37,BD!B$1:C$261,2,FALSE) -> #N/A | M37: =VLOOKUP(L37,BD!D$1:E$6,2,FALSE) -> #N/A | R37: =VLOOKUP(Q37,BD!F$1:G$22,2,FALSE) -> #N/A | U37: =VLOOKUP(T37,BD!H$1:I$8,2,FALSE) -> #N/A | W37: =VLOOKUP(V37,BD!B$1:C$261,2,FALSE) -> #N/A
J38: =VLOOKUP(I38,BD!B$1:C$261,2,FALSE) -> #N/A | M38: =VLOOKUP(L38,BD!D$1:E$6,2,FALSE) -> #N/A | R38: =VLOOKUP(Q38,BD!F$1:G$22,2,FALSE) -> #N/A | U38: =VLOOKUP(T38,BD!H$1:I$8,2,FALSE) -> #N/A | W38: =VLOOKUP(V38,BD!B$1:C$261,2,FALSE) -> #N/A
J39: =VLOOKUP(I39,BD!B$1:C$261,2,FALSE) -> #N/A | M39: =VLOOKUP(L39,BD!D$1:E$6,2,FALSE) -> #N/A | R39: =VLOOKUP(Q39,BD!F$1:G$22,2,FALSE) -> #N/A | U39: =VLOOKUP(T39,BD!H$1:I$8,2,FALSE) -> #N/A | W39: =VLOOKUP(V39,BD!B$1:C$261,2,FALSE) -> #N/A
J40: =VLOOKUP(I40,BD!B$1:C$261,2,FALSE) -> #N/A | M40: =VLOOKUP(L40,BD!D$1:E$6,2,FALSE) -> #N/A | R40: =VLOOKUP(Q40,BD!F$1:G$22,2,FALSE) -> #N/A | U40: =VLOOKUP(T40,BD!H$1:I$8,2,FALSE) -> #N/A | W40: =VLOOKUP(V40,BD!B$1:C$261,2,FALSE) -> #N/A
...

Sheet BD
A1: CC | B1: DESC_PAIS | C1: ID_PAIS | D1: Pasantía o práctica | E1: 1 | F1: DESC_FUENTE_NACIONAL_INVESTIG | G1: ID_FUENTE_NACIONAL_INVESTIG | H1: Sector Empresarial | I1: 1 | J1: S
A2: DE | B2: AFGANISTÁN | C2: 4 | D2: Misión | E2: 2 | F2: Recursos IES | G2: 1 | H2: Sector Administración Pública | I2: 2 | J2: N
A3: CE | B3: ALBANIA | C3: 8 | D3: Curso corto | E3: 3 | F3: Recursos públicos nacionales - Colciencias | G3: 2 | H3: Centros de Investigación y Desarrollo Tecnológico | I3: 3
A4: TI | B4: ALEMANIA | C4: 276 | D4: Asistencia a eventos | E4: 4 | F4: Recursos públicos nacionales - SENA | G4: 3 | H4: Hospitales y Clínicas | I4: 4
A5: PS | B5: ANDORRA | C5: 20 | D5: Rotación Médica | E5: 5 | F5: Recursos públicos nacionales - Ministerio del Interior y Justicia | G5: 4 | H5: Instituciones privadas sin ánimo de lucro | I5: 5
A6: CA | B6: ANGOLA | C6: 24 | D6: Curso de español | E6: 6 | F6: Recursos públicos nacionales - Ministerio de Relaciones Exteriores | G6: 5 | H6: Instituciones de Educación Superior | I6: 6
B7: ANGUILA | C7: 660 | F7: Recursos públicos nacionales - Ministerio de Hacienda y Crédito Público | G7: 6 | H7: Organismo Multilateral | I7: 7
B8: ANTÁRTIDA | C8: 10 | F8: Recursos públicos nacionales - Ministerio de Defensa Nacional | G8: 7 | H8: Otra | I8: 8
B9: ANTIGUA Y BARBUDA | C9: 28 | F9: Recursos públicos nacionales - Ministerio de Agricultura y Desarrollo rural | G9: 8
B10: ANTILLAS NEERLANDESAS | C10: 530 | F10: Recursos públicos nacionales - Ministerio de Protección Social | G10: 9
B11: ARABIA SAUDITA | C11: 682 | F11: Recursos públicos nacionales - Ministerio de Minas y Energía | G11: 10
B12: ARGELIA | C12: 12 | F12: Recursos públicos nacionales - Ministerio de Comercio, Industria y Turismo | G12: 11
B13: ARGENTINA | C13: 32 | F13: Recursos públicos nacionales - Ministerio de Educación Nacional | G13: 12
B14: ARMENIA | C14: 51 | F14: Recursos públicos nacionales - Ministerio de Ambiente, Vivienda y Desarrollo Territorial | G14: 13
B15: ARUBA | C15: 533 | F15: Recursos públicos nacionales - Ministerio de Comunicaciones | G15: 14
B16: AUSTRALIA | C16: 36 | F16: Recursos públicos nacionales - Ministerio de Transporte | G16: 15
B17: AUSTRIA | C17: 40 | F17: Recursos públicos nacionales - Ministerio de Cultura | G17: 16
B18: AZERBAIYÁN | C18: 31 | F18: Recursos públicos departamentales | G18: 17
B19: BAHAMAS | C19: 44 | F19: Recursos públicos municipales o distritales | G19: 18
B20: BAHRÉIN | C20: 48 | F20: Recursos Privadas | G20: 19
... B22: BARBADOS | C22: 52 | F22: Recursos Personales | G22: 21
B23: BELARÚS | C23: 112
B24: BELGICA | C24: 87
B25: BÉLGICA | C25: 56
B26: BELICE | C26: 84
B27: BENÍN | C27: 204
B28: BERMUDAS | C28: 60
B29: BHUTÁN | C29: 64
B30: BOLIVIA | C30: 68
B31: BONAIRE, SAN EUSTAQUIO Y SABA | C31: 535
B32: BOSNIA Y HERZEGOVINA | C32: 70
B33: BOTSUANA | C33: 72
B34: BRASIL | C34: 76
... B261: ZIMBABWE | C261: 716

Sheet INFO
A1: Información de Control. No editar, mover o eliminar esta hoja.
A2: Nombre de la Plantilla | B2: Movilidad de estudiantes del exterior hacia colombia
A3: Descripción de la Plantilla | B3: Movilidad de estudiantes del exterior hacia Colombia
A4: Código de la Plantilla | B4: 101
